Workbook

Sheet Summary
A1: Quickair HR — data import review
A2: Generated 12 Oct 2026 from the files supplied by the user
A4: Item | B4: Count
A5: employees | B5: 53
A6: skillSheets | B6: 10
A7: skillPeople | B7: 24
A8: skillLinked | B8: 8
A10: Flags — high | B10: 16
A11: Flags — medium | B11: 7
A12: Flags — low | B12: 16
A14: How to use
A15: 1. "Flags" lists every issue found; nothing was filled in with dummy values.
A16: 2. "Skill links": confirm the 8 name-matched links; for the rest enter the correct code in the yellow column.

Sheet Flags
A1: Severity | B1: Area | C1: Item | D1: Detail
A2: high | B2: Skill matrix | C2: Assembly › Tejaswini | D2: Not in employee master — shown in Skills only, no code assigned
A3: high | B3: Skill matrix | C3: Assembly › Laxman | D3: Not in employee master — shown in Skills only, no code assigned
A4: high | B4: Skill matrix | C4: Store › Shivalingaih | D4: Not in employee master — shown in Skills only, no code assigned
A5: high | B5: Skill matrix | C5: Store › Santhosh | D5: Ambiguous — matches CAPL_1057 Santhosh R, CAPL_1121 Santhosh S H — not linked
A6: high | B6: Skill matrix | C6: Testing › Shivam | D6: Not in employee master — shown in Skills only, no code assigned
A7: high | B7: Skill matrix | C7: Testing › Pankaj | D7: Not in employee master — shown in Skills only, no code assigned
A8: high | B8: Skill matrix | C8: Pipe Section › Satish | D8: Ambiguous — matches CAPL_1038 Sathish B, CAPL_1124 Gutte Sathish — not linked
A9: high | B9: Skill matrix | C9: Pipe Section › Ashoka | D9: Not in employee master — shown in Skills only, no code assigned
A10: high | B10: Skill matrix | C10: Machine Shop › Abzal | D10: Not in employee master — shown in Skills only, no code assigned
A11: high | B11: Skill matrix | C11: Internal Sales › Shilpa kumar | D11: Not in employee master — shown in Skills only, no code assigned
A12: high | B12: Skill matrix | C12: Conveyor › MAHESH M | D12: Not in employee master — shown in Skills only, no code assigned
... A40: low | B40: Skill matrix | C40: Machine Shop › Abzal | D40: Current above Expected for: AS 9100 Rev D Basic Awarness ( Product / Processs), Personal Safety — check whether columns were swapped

Sheet Skill links
A1: Department | B1: Name in skill sheet | C1: ID in sheet | D1: Match | E1: Linked code | F1: Candidates | G1: Correct code (fill) | H1: Master name (auto)
A2: Assembly | B2: Jayamma | D2: exact | E2: CAPL_1014 | F2: CAPL_1014 | H2: =IF(G2="","",IFERROR(INDEX('Employee master'!$B$2:$B$54,MATCH(G2,'Employee master'!$A$2:$A$54,0)),"Code not in master"))
A3: Assembly | B3: Tejaswini | D3: none | H3: =IF(G3="","",IFERROR(INDEX('Employee master'!$B$2:$B$54,MATCH(G3,'Employee master'!$A$2:$A$54,0)),"Code not in master"))
A4: Assembly | B4: Laxman | D4: none | H4: =IF(G4="","",IFERROR(INDEX('Employee master'!$B$2:$B$54,MATCH(G4,'Employee master'!$A$2:$A$54,0)),"Code not in master"))
A5: Store | B5: Ramakrishna | D5: name | E5: CAPL_1086 | F5: CAPL_1086 | H5: =IF(G5="","",IFERROR(INDEX('Employee master'!$B$2:$B$54,MATCH(G5,'Employee master'!$A$2:$A$54,0)),"Code not in master"))
A6: Store | B6: Ganesha | D6: name | E6: CAPL_1032 | F6: CAPL_1032 | H6: =IF(G6="","",IFERROR(INDEX('Employee master'!$B$2:$B$54,MATCH(G6,'Employee master'!$A$2:$A$54,0)),"Code not in master"))
A7: Store | B7: Shivalingaih | D7: none | H7: =IF(G7="","",IFERROR(INDEX('Employee master'!$B$2:$B$54,MATCH(G7,'Employee master'!$A$2:$A$54,0)),"Code not in master"))
A8: Store | B8: Santhosh | D8: ambiguous | F8: CAPL_1057, CAPL_1121 | H8: =IF(G8="","",IFERROR(INDEX('Employee master'!$B$2:$B$54,MATCH(G8,'Employee master'!$A$2:$A$54,0)),"Code not in master"))
A9: Testing | B9: Shivam | D9: none | H9: =IF(G9="","",IFERROR(INDEX('Employee master'!$B$2:$B$54,MATCH(G9,'Employee master'!$A$2:$A$54,0)),"Code not in master"))
A10: Testing | B10: Pankaj | D10: none | H10: =IF(G10="","",IFERROR(INDEX('Employee master'!$B$2:$B$54,MATCH(G10,'Employee master'!$A$2:$A$54,0)),"Code not in master"))
A11: Pipe Section | B11: Satish | D11: ambiguous | F11: CAPL_1038, CAPL_1124 | H11: =IF(G11="","",IFERROR(INDEX('Employee master'!$B$2:$B$54,MATCH(G11,'Employee master'!$A$2:$A$54,0)),"Code not in master"))
A12: Pipe Section | B12: Ashoka | D12: none | H12: =IF(G12="","",IFERROR(INDEX('Employee master'!$B$2:$B$54,MATCH(G12,'Employee master'!$A$2:$A$54,0)),"Code not in master"))
A13: Machine Shop | B13: Renukaprasad | D13: name | E13: CAPL_1034 | F13: CAPL_1034 | H13: =IF(G13="","",IFERROR(INDEX('Employee master'!$B$2:$B$54,MATCH(G13,'Employee master'!$A$2:$A$54,0)),"Code not in master"))
A14: Machine Shop | B14: Amith | D14: name | E14: CAPL_1033 | F14: CAPL_1033 | H14: =IF(G14="","",IFERROR(INDEX('Employee master'!$B$2:$B$54,MATCH(G14,'Employee master'!$A$2:$A$54,0)),"Code not in master"))
A15: Machine Shop | B15: Velu | D15: exact | E15: CAPL_1036 | F15: CAPL_1036 | H15: =IF(G15="","",IFERROR(INDEX('Employee master'!$B$2:$B$54,MATCH(G15,'Employee master'!$A$2:$A$54,0)),"Code not in master"))
A16: Machine Shop | B16: Abzal | D16: none | H16: =IF(G16="","",IFERROR(INDEX('Employee master'!$B$2:$B$54,MATCH(G16,'Employee master'!$A$2:$A$54,0)),"Code not in master"))
A17: Internal Sales | B17: Shilpa kumar | D17: none | H17: =IF(G17="","",IFERROR(INDEX('Employee master'!$B$2:$B$54,MATCH(G17,'Employee master'!$A$2:$A$54,0)),"Code not in master"))
A18: Conveyor | B18: MAHESH M | D18: none | H18: =IF(G18="","",IFERROR(INDEX('Employee master'!$B$2:$B$54,MATCH(G18,'Employee master'!$A$2:$A$54,0)),"Code not in master"))
A19: Conveyor | B19: SHANKAR | C19: EC196 | D19: none | H19: =IF(G19="","",IFERROR(INDEX('Employee master'!$B$2:$B$54,MATCH(G19,'Employee master'!$A$2:$A$54,0)),"Code not in master"))
A20: Conveyor | B20: YESHWANTH S | C20: EC188 | D20: none | H20: =IF(G20="","",IFERROR(INDEX('Employee master'!$B$2:$B$54,MATCH(G20,'Employee master'!$A$2:$A$54,0)),"Code not in master"))
A21: Quality | B21: Prashanth | D21: none | H21: =IF(G21="","",IFERROR(INDEX('Employee master'!$B$2:$B$54,MATCH(G21,'Employee master'!$A$2:$A$54,0)),"Code not in master"))
A22: Quality | B22: Shivukumar | D22: name | E22: CAPL_1007 | F22: CAPL_1007 | H22: =IF(G22="","",IFERROR(INDEX('Employee master'!$B$2:$B$54,MATCH(G22,'Employee master'!$A$2:$A$54,0)),"Code not in master"))
A23: Quality | B23: Lohith | D23: none | H23: =IF(G23="","",IFERROR(INDEX('Employee master'!$B$2:$B$54,MATCH(G23,'Employee master'!$A$2:$A$54,0)),"Code not in master"))
A24: Moulding | B24: Mohan | D24: ambiguous | F24: CAPL_1052, CAPL_1122 | H24: =IF(G24="","",IFERROR(INDEX('Employee master'!$B$2:$B$54,MATCH(G24,'Employee master'!$A$2:$A$54,0)),"Code not in master"))
A25: Moulding | B25: Ravindra | D25: name | E25: CAPL_1131 | F25: CAPL_1131 | H25: =IF(G25="","",IFERROR(INDEX('Employee master'!$B$2:$B$54,MATCH(G25,'Employee master'!$A$2:$A$54,0)),"Code not in master"))

Sheet Employee master
A1: Employee code | B1: Name | C1: Department (from skill matrix)
A2: CAPL_1001 | B2: H S Gajanan
A3: CAPL_1002 | B3: Shubha Gajanan
A4: CAPL_1003 | B4: Jayakanth E
A5: CAPL_1004 | B5: Mahesh V H
A6: CAPL_1006 | B6: Ramji Lal
A7: CAPL_1007 | B7: Shivakumar G H | C7: Quality
A8: CAPL_1009 | B8: Lakshmi
A9: CAPL_1010 | B9: M Krishnappa
A10: CAPL_1014 | B10: Jayamma | C10: Assembly
A11: CAPL_1017 | B11: R Hemalatha
A12: CAPL_1021 | B12: Pramod K
A13: CAPL_1023 | B13: Raghavendra M R
A14: CAPL_1025 | B14: Priyanka C H
A15: CAPL_1027 | B15: Balakrishna R
A16: CAPL_1030 | B16: Rohit Kumar Ray
A17: CAPL_1032 | B17: Ganesh Govintharaju | C17: Store
A18: CAPL_1033 | B18: Amit Kumar Rai | C18: Machine Shop
A19: CAPL_1034 | B19: Renuka Prasad N | C19: Machine Shop
A20: CAPL_1036 | B20: C Velu | C20: Machine Shop
A21: CAPL_1038 | B21: Sathish B
A22: CAPL_1052 | B22: Mohana K N
A23: CAPL_1057 | B23: Santhosh R
A24: CAPL_1063 | B24: Neelkanth Goura
A25: CAPL_1064 | B25: Kumaran Venkatesan
A26: CAPL_1074 | B26: Mallikarjuna MO
A27: CAPL_1080 | B27: Omkeshwaraiah
A28: CAPL_1083 | B28: Lokamathe K
A29: CAPL_1086 | B29: Ramakrishna Kodagunti | C29: Store
A30: CAPL_1087 | B30: Vinod S
A31: CAPL_1088 | B31: Harikishan Yadav
A32: CAPL_1098 | B32: Sharana Basava
A33: CAPL_1101 | B33: Renukaradhya
A34: CAPL_1108 | B34: Chaithra H N
A35: CAPL_1110 | B35: Vipin Kumar A R
A36: CAPL_1111 | B36: Gopi M
A37: CAPL_1117 | B37: Premkumar Singh
A38: CAPL_1118 | B38: Virupaksha M K
A39: CAPL_1119 | B39: Sakamma
A40: CAPL_1120 | B40: Jayalakshmi
...
